Workbook

Sheet New Alumni DB
A1: ID | B1: Associate Number | C1: Full Name | D1: Surname | E1: First Name | F1: Middle Name | G1: Age Group | H1: Phone number | I1: Email | J1: Second Email | K1: LinkedIn | L1: Current Firm | M1: Current Role | N1: Current Role Seniority | O1: Current City | P1: Current Country | Q1: Curent Industry | R1: Notable Past Firms | S1: Past Role NPF | T1: Starting month NPF | U1: Ending Month NPF | V1: PR City | W1: PR City 2 | X1: PR City 3 | Y1: PR Country | Z1: PR Country 2 | AA1: PR Country 3 | AB1: NPF Industry | AC1: JEME Starting Period | AD1: JEME Ending Period | AE1: JEME Role | AF1: JEME Role 2 | AG1: JEME Role 3 | AH1: Board | AI1: Head
A2: 324 | B2: 329 | C2: Agnieszka Kania | D2: Kania | E2: Agnieszka | G2: 35-40 | I2: lesniewska.agnieszka@gmail.com | K2: https://www.linkedin.com/ignieszkadariakania/ | L2: Gsk | M2: Senior Manager Regulatory Platform Innovation | N2: C Level | O2: Milan | P2: IT | Q2: Healthcare & Pharma | R2: dotOne | S2: Business Analyst | T2: 01/2012 | U2: 01/2013 | V2: Kraków | Y2: PL | AB2: Technology & Software | AC2: 39387 | AD2: 40179 | AE2: Head of HR | AF2: Administrator | AH2: TRUE | AI2: TRUE
A3: 581 | B3: 70 | C3: Aiste Bielinyte | D3: Bielinyte | E3: Aiste | G3: 20-25 | I3: aiste.bielinyte@pimco.com | K3: https://www.linkedin.com/in/aistebielinyte/ | L3: PIMCO | M3: Account Analyst | N3: Entry level | O3: London | P3: GB | Q3: Financial Services | R3: Coinvest Capital | S3: Summer Intern | T3: 01/2022 | U3: 01/2022 | V3: Vilnius | Y3: LT | AB3: Financial Services | AC3: 44563 | AD3: 44929 | AE3: Associate Consultant | AH3: FALSE | AI3: FALSE
A4: 270 | B4: 2 | C4: Alberto Accogli | D4: Accogli | E4: Alberto | G4: 35-40 | I4: alberto.accogli@gmail.com | K4: https://www.linkedin.com/ilberto-accogli/ | L4: Boston Consulting Group (BCG) | M4: Principal | N4: Middle Level | O4: Dubai | P4: AE | Q4: Consulting & Advisory | R4: Leoni Corporate Advisors | S4: Manager | T4: 01/2012 | U4: 01/2019 | V4: Milan | Y4: IT | AB4: Consulting & Advisory | AC4: 38732 | AD4: 39447 | AE4: Secretary General | AF4: Head of HR | AH4: TRUE | AI4: TRUE
A5: 488 | B5: 20 | C5: Alberto Antoniolli | D5: Antoniolli | E5: Alberto | G5: 25-30 | I5: alberto.antoniolli@gmail.com | K5: https://www.linkedin.com/ilbertoantoniolli/ | L5: Lazard | M5: M&A Analyst | N5: Entry Level | O5: Milan | P5: IT | Q5: Consulting & Advisory | R5: Italmobiliare S.p.A. | S5: Intern Financial Analyst | T5: 06/2021 | U5: 09/2019 | V5: Milan | Y5: IT | AB5: Financial Services | AC5: 43626 | AD5: 44743 | AE5: Treasurer | AH5: TRUE | AI5: FALSE
A6: 526 | B6: 123 | C6: Alberto Cattaruzza | D6: Cattaruzza | E6: Alberto | G6: 25-30 | I6: cattaruzza98@gmail.com | K6: https://www.linkedin.com/in/alberto-cattaruzza-804a1a196/ | L6: Blackstone | M6: Associate | N6: Entry Level | O6: Milan | P6: IT | Q6: Financial Services | R6: Bank of America | S6: Investment Banking Analyst | T6: 07/2022 | U6: 12/2024 | V6: Milan | Y6: IT | AB6: Financial Services | AC6: 43891 | AD6: 44470 | AE6: Associate Consultant | AH6: FALSE | AI6: FALSE
B7: 138 | C7: Alberto Cifrodelli | D7: Cifrodelli | E7: Alberto | G7: 20-25 | I7: alberto.cifrodelli@studbocconi.it | K7: https://www.linkedin.com/in/albertocifrodelli | L7: BNP Paribas CIB | M7: Docente Master, Componente del Comitato Scientifico del Laboratorio di Finanza Decentralizzata e Blockchain (LabDEC) | N7: Entry level | O7: Milan | Q7: Financial Services | R7: Resolute Asset Management | S7: Co-Founder | T7: 01/2023 | U7: 01/2023 | V7: Milan | Y7: IT | AB7: Financial Services | AE7: Associate Consultant | AH7: FALSE | AI7: FALSE
A8: 202 | B8: 250 | C8: Alberto Franco | D8: Franco | E8: Alberto | I8: alberto.franco@cbalex.com | K8: https://www.linkedin.com/ilbertofrancoit | L8: Saa - School Ofnmanagement, Università Di Torino | M8: M&A Analyst | N8: Middle level | O8: Turin | P8: IT | Q8: Legal & Compliance | R8: CryptoLeges | S8: Financial Analyst | T8: 01/2015 | U8: Present | V8: Turin | Y8: IT | AB8: Education & Research | AE8: Associate Consultant | AH8: FALSE | AI8: FALSE
A9: 511 | B9: 320 | C9: Alberto Holler | D9: Holler | E9: Alberto | G9: 25-30 | I9: alberto.holler@gmail.com | K9: https://www.linkedin.com/ilberto-holler-72a95199/ | L9: Generali | M9: Investment Banking Off-Cycle Analyst | N9: Entry level | O9: Milan | P9: IT | Q9: Financial Services | R9: Deloitte | S9: Investment Analyst Intern | T9: 06/2021 | U9: 09/2021 | V9: Milan | Y9: IT | AB9: Consulting & Advisory | AC9: 43843 | AD9: 44627 | AE9: Secretary General | AH9: TRUE | AI9: FALSE
A10: 106 | B10: 386 | C10: Alberto Matuozzo | D10: Matuozzo | E10: Alberto | G10: 45-50 | I10: a.matuozzo@virtuosoadvisory.com | J10: alberto_matuozzo@yahoo.co.uk | K10: https://www.linkedin.com/in/alberto-matuozzo-2a504a8/ | L10: Virtuoso Advisory | M10: Director | N10: C Level | O10: London | P10: GB | Q10: Financial Services | R10: Farema Capital | S10: Partner | T10: 01/2012 | U10: 04/2016 | V10: London | Y10: GB | AB10: Financial Services | AC10: 35104 | AD10: 35766 | AE10: President | AH10: TRUE | AI10: FALSE
B11: 587 | C11: Alberto Vedovi | D11: Vedovi | E11: Alberto | G11: 30-35 | I11: albertovedovi@gmail.com | K11: https://www.linkedin.com/in/alberto-vedovi-cfa-caia-48832772/ | L11: NS Partners | M11: Principal Director | N11: Middle Level | O11: Luxembourg | Q11: Financial Services | R11: Deloitte | S11: Sustainability and Innovation Officer | T11: 01/2018 | U11: 09/2020 | V11: Luxembourg | Y11: LU | AB11: Consulting & Advisory | AC11: 42095 | AD11: 43040 | AE11: Vice President | AF11: Treasurer | AH11: TRUE | AI11: FALSE
A12: 174 | B12: 479 | C12: Aldo Pozzoli | D12: Pozzoli | E12: Aldo | G12: 40-45 | I12: aldopozzoli@hotmail.com | K12: https://www.linkedin.com/in/aldopozzoli/ | L12: Accenture | M12: Client Business Partner | N12: C Level | O12: Milan | P12: IT | Q12: Consulting & Advisory | R12: Comune di Milano | S12: International Business Senior Consultant | T12: 01/2007 | U12: 01/2011 | V12: Milan | Y12: IT | AB12: Public Sector & Non-Profit | AC12: 36871 | AD12: 37649 | AE12: Associate Consultant | AH12: FALSE | AI12: FALSE
A13: 217 | B13: 29 | C13: Alessandra Arrigoni | D13: Arrigoni | E13: Alessandra | G13: 40-45 | I13: alessandraarrigoni@hotmail.com | K13: https://www.linkedin.com/in/alessandra-arrigoni-8aa45b7/ | L13: NielsenIQ | M13: Financial Stability Intern | N13: C Level | O13: London | P13: GB | Q13: Technology & Software | R13: Nielsen | S13: Strategy Analyst Intern | T13: 01/2014 | U13: 01/2015 | V13: London | Y13: GB | AB13: Technology & Software | AC13: 37642 | AD13: 38007 | AE13: Associate Consultant | AH13: FALSE | AI13: FALSE
A14: 603 | B14: 238 | C14: Alessandra Fidone | D14: Fidone | E14: Alessandra | G14: 20-25 | I14: alessandrafidone@outlook.com | K14: https://www.linkedin.com/in/alessandrafidone/ | L14: Deutsche Bundesbank | N14: Entry level | O14: Frankfurt | P14: DE | Q14: Financial Services | R14: Knauf Insulation | T14: 01/2023 | U14: 01/2023 | V14: Brussels | Y14: BE | AB14: Industrial & Manufacturing | AC14: 44571 | AD14: 45666 | AE14: Head of Marketing | AH14: FALSE | AI14: TRUE
A15: 126 | B15: 268 | C15: Alessandra Galli | D15: Galli | E15: Alessandra | G15: 45-50 | I15: ale.galli76@gmail.com | M15: Corporate Tax Advisor | S15: Technical Advisor to the Judge | AC15: 35831 | AD15: 35990 | AE15: Associate Consultant | AH15: FALSE | AI15: FALSE
A16: 77 | B16: 357 | C16: Alessandra Mangeri | D16: Mangeri | E16: Alessandra | G16: 50-55 | I16: ale.mangeri@virgilio.it | K16: https://www.linkedin.com/in/alessandra-mangeri-6568903b/ | L16: Amg | M16: Distribution Manager | N16: Middle Level | O16: Cuneo | P16: IT | Q16: Financial Services | R16: Tribunale di Brescia | S16: Area Manager | T16: 01/2011 | U16: Present | V16: Brescia | Y16: IT | AB16: Public Sector & Non-Profit | AC16: 33865 | AD16: 37315 | AE16: Associate Consultant | AH16: FALSE | AI16: FALSE
A17: 307 | B17: 457 | C17: Alessandra Peres | D17: Peres | E17: Alessandra | G17: 35-40 | I17: alessandra_peres@swissre.com | K17: https://www.linkedin.com/ilessandra-peres-21b2a2b/ | L17: Swiss Re Corporate Solutions | M17: Vice President Customer Value Creation | N17: Middle Level | O17: Milan | P17: IT | Q17: Financial Services | R17: FC Rimaco - Stellantis | S17: Product innovation and business director | T17: 01/2020 | U17: 01/2023 | V17: Lugano | Y17: CH | AB17: Financial Services | AC17: 39329 | AD17: 40513 | AE17: Vice President | AH17: FALSE | AI17: FALSE
A18: 131 | B18: 599 | C18: Alessandra Vultaggio | D18: Vultaggio | E18: Alessandra | G18: 45-50 | I18: alexvulty@gmail.com | K18: https://www.linkedin.com/in/alessandravultaggio/ | L18: Global Blue | M18: Senior Advisor | N18: C Level | O18: Milan | P18: IT | Q18: Financial Services | R18: Edenred Italia | S18: Group Chief Information Officer | T18: 05/2011 | U18: 11/2019 | V18: Milan | Y18: IT | AB18: Financial Services | AC18: 35831 | AD18: 37298 | AE18: President | AH18: TRUE | AI18: FALSE
A19: 6 | B19: 9 | C19: Alessandro Alloisio | D19: Alloisio | E19: Alessandro | G19: 55-60 | I19: alessandroalloisio@gmail.com | K19: https://www.linkedin.com/ilessandro-alloisio-9a13a/ | L19: Freelancer (Self-Employed) | O19: Como | P19: IT | R19: Sanlorenzo | T19: 01/2021 | U19: 10/2025 | V19: Ameglia | Y19: IT | AB19: Consumer & Retail | AC19: 32464 | AD19: 34233 | AE19: Administrator | AH19: TRUE | AI19: FALSE
A20: 1 | B20: 52 | C20: Alessandro Bellotti | D20: Bellotti | E20: Alessandro | M20: Responsabile Specialisti Investimenti | S20: District manager | AH20: FALSE | AI20: FALSE
A21: 72 | B21: 84 | C21: Alessandro Brambilla | D21: Brambilla | E21: Alessandro | G21: 50-55 | K21: https://www.linkedin.com/in/alessandro-brambilla-24522121/ | L21: Mediobanca Premier | M21: Investment Professional | N21: Middle Level | O21: Milan | P21: IT | Q21: Financial Services | R21: Barclays | S21: Associate | T21: 01/2013 | U21: 08/2016 | V21: Milan | Y21: IT | AB21: Financial Services | AC21: 33419 | AD21: 34466 | AE21: President | AH21: TRUE | AI21: FALSE
A22: 411 | B22: 90 | C22: Alessandro Brutto | D22: Brutto | E22: Alessandro | G22: 25-30 | I22: bruttoalessandro@gmail.com | K22: https://www.linkedin.com/ilessandro-brutto-bb15117 | L22: Cinven | M22: Staff Product Manager | N22: Middle Level | O22: London | P22: GB | Q22: Financial Services | R22: Goldman Sachs | S22: Head of Product | T22: 11/2021 | U22: 06/2024 | V22: London | Y22: GB | AB22: Financial Services | AC22: 42513 | AD22: 42790 | AE22: Associate Consultant | AH22: FALSE | AI22: FALSE
A23: 426 | B23: 174 | C23: Alessandro Dadone | D23: Dadone | E23: Alessandro | G23: 25-30 | I23: aledadone@gmail.com | K23: https://www.linkedin.com/ilessandro-dadone-23196318 | L23: Qonto | M23: Associate | N23: Middle Level | O23: Paris | P23: FR | Q23: Financial Services | R23: Casavo | S23: Consultant | T23: 05/2022 | U23: 03/2024 | V23: Milan | Y23: IT | AB23: Technology & Software | AC23: 42751 | AD23: 43472 | AE23: Associate Consultant | AH23: FALSE | AI23: FALSE
A24: 429 | B24: 242 | C24: Alessandro Filoramo | D24: Filoramo | E24: Alessandro | I24: alessandro.filoram@gmail.com | K24: https://www.linkedin.com/ilessandrofiloramo | L24: Oliver Wyman | M24: Vice-President | N24: Entry level | O24: Dubai | P24: AE | Q24: Consulting & Advisory | R24: Arthur D. Little | S24: Vice President | T24: 09/2021 | U24: 03/2024 | V24: Dubai | Y24: AE | AB24: Consulting & Advisory | AE24: President | AH24: FALSE | AI24: FALSE
A25: 192 | B25: 261 | C25: Alessandro Gagliardi | D25: Gagliardi | E25: Alessandro | G25: 45-50 | I25: alessandro.gagliardi@hsbc.com | K25: https://www.linkedin.com/ilessandro-gagliardi/ | L25: Hsbc | M25: GTM Manager | N25: C Level | O25: London | P25: GB | Q25: Financial Services | R25: GE Capital | S25: M&A Intern | T25: 09/2008 | U25: 07/2016 | V25: London | Y25: GB | AB25: Financial Services | AC25: 37013 | AD25: 37298 | AE25: Associate Consultant | AH25: FALSE | AI25: FALSE
A26: 514 | B26: 393 | C26: Alessandro Medico | D26: Medico | E26: Alessandro | G26: 25-30 | H26: +393331968961 | I26: alemedi@icloud.com | K26: https://www.linkedin.com/ilessandro-medico/ | L26: Revel8 | M26: Investment Banking Analyst | N26: Middle Level | O26: Berlin | P26: DE | Q26: Technology & Software | R26: Bending Spoons | S26: Investment Banking Analyst | T26: 01/2021 | U26: 04/2022 | V26: Milan | Y26: IT | AB26: Technology & Software | AE26: Associate Consultant | AH26: FALSE | AI26: FALSE
A27: 561 | B27: 441 | C27: Alessandro Paladino | D27: Paladino | E27: Alessandro | G27: 25-30 | I27: alessandro.paladino.ts@gmail.com | K27: https://www.linkedin.com/in/alessandropaladino/ | L27: Morgan Stanley | M27: President | N27: Entry level | O27: Dubai | P27: AE | Q27: Financial Services | R27: Rothschild & Co | S27: Engagement Manager | T27: 01/2024 | U27: 01/2024 | V27: Dubai | Y27: AE | AB27: Financial Services | AE27: Secretary General | AH27: TRUE | AI27: TRUE
A28: 255 | B28: 487 | C28: Alessandro Radici | D28: Radici | E28: Alessandro | G28: 40-45 | I28: alessandro.radici@seragro.com.ar | K28: https://www.linkedin.com/ilessandro-radici-9988317/ | L28: Ser Beef | M28: Graduate Management Trainee | N28: C Level | O28: San Luis | Q28: Consulting & Advisory | R28: McKinsey & Company | S28: Corporate Finance Intern | T28: 08/2012 | U28: 07/2015 | V28: New Jersey | Y28: US | AB28: Consulting & Advisory | AC28: 38356 | AD28: 39083 | AE28: Vice President | AH28: TRUE | AI28: FALSE
A29: 610 | B29: 550 | C29: Alessandro Sozzani | D29: Sozzani | E29: Alessandro | G29: 25-30 | I29: alessandro.sozzani@hotmail.it | J29: alessandro.sozzani@ab-inbev.com | K29: https://www.linkedin.com/in/alessandro-sozzani/ | L29: AB InBev | M29: Fund Administration Analyst | N29: Entry level | P29: US | R29: Barilla Group | S29: Junior Aufitor | T29: 01/2024 | U29: 01/2024 | V29: Singapore | Y29: SG | AB29: Food & Beverage | AC29: 44571 | AD29: 45663 | AE29: Associate Consultant | AH29: FALSE | AI29: FALSE
A30: 553 | B30: 576 | C30: Alessandro Trisciuoglio | D30: Trisciuoglio | E30: Alessandro | G30: 25-30 | I30: aletrisc@gmail.com | K30: https://www.linkedin.com/ilessandro-trisciuoglio/ | L30: Heritage Holdings | M30: Senior Financial Analyst | N30: Entry Level | O30: Milan | P30: IT | Q30: Financial Services | R30: PwC | S30: Intern | T30: 01/2023 | U30: 01/2023 | V30: Milan | Y30: IT | AB30: Consulting & Advisory | AC30: 44075 | AD30: 44562 | AE30: Associate Consultant | AH30: FALSE | AI30: FALSE
A31: 472 | B31: 3 | C31: Alessia Acquistapace | D31: Acquistapace | E31: Alessia | G31: 25-30 | I31: alessia.a@amazon.com | K31: https://www.linkedin.com/in/alessiaacquistapace/ | L31: Amazon | M31: Praticante Notaio | N31: Middle Level | O31: London | P31: GB | Q31: Consumer & Retail | R31: Rothschild & Co | S31: Praticante Avvocato | T31: 06/2021 | U31: 01/2021 | V31: Milan | Y31: IT | AB31: Financial Services | AC31: 43255 | AD31: 44835 | AE31: Associate Consultant | AH31: FALSE | AI31: FALSE
A32: 469 | B32: 8 | C32: Alessia Alberti | D32: Alberti | E32: Alessia | G32: 25-30 | I32: alessia.alberti96@gmail.com | K32: https://www.linkedin.com/ilessia-alberti-b75a612b/ | L32: Roveda Laurini Clerici D’Amore Notai | M32: Dottore Commercialista - Revisore Legale | N32: Entry level | O32: Milan | P32: IT | Q32: Legal & Compliance | R32: BonelliErede | S32: Dottore Commercialista - Revisore Legale | T32: 02/2022 | U32: 07/2022 | V32: Milan | Y32: IT | AB32: Legal & Compliance | AC32: 43255 | AD32: 43871 | AE32: Associate Consultant | AH32: FALSE | AI32: FALSE
A33: 124 | B33: 197 | C33: Alessia Della Vedova | D33: Della Vedova | E33: Alessia | G33: 45-50 | K33: https://www.linkedin.com/ilessia-dellavedova/ | L33: Ls Lexjus Sinacta | M33: Managing Director Italy | N33: Entry level | Q33: Legal & Compliance | R33: Russo De Rosa Associati | S33: Go-to-Market Strategy Senior Manager | T33: 09/2019 | U33: 06/2024 | V33: Milan | Y33: IT | AB33: Legal & Compliance | AC33: 35831 | AD33: 36121 | AE33: Associate Consultant | AH33: FALSE | AI33: FALSE
A34: 361 | B34: 244 | C34: Alessia Fontanari | D34: Fontanari | E34: Alessia | G34: 30-35 | I34: alessiafon@gmail.com | J34: alessia@mapotapo.com | K34: https://www.linkedin.com/ilessiafontanari | L34: Flatpay | M34: CEO and owner | N34: C Level | O34: Milan | P34: IT | Q34: Financial Services | R34: Doctolib | S34: Consultant | T34: 01/2022 | U34: 12/2024 | V34: Milan | Y34: IT | AB34: Healthcare & Pharma | AC34: 41310 | AD34: 42499 | AE34: Head of Sales | AH34: FALSE | AI34: TRUE
A35: 112 | B35: 87 | C35: Alessio Bressan | D35: Bressan | E35: Alessio | G35: 45-50 | I35: alessio.bressan@igbressan.it | K35: https://www.linkedin.com/ilessio-bressan-8b26b/ | L35: IGB - Industrie Grafiche Bressan | M35: Owner | N35: C Level | O35: Milan | P35: IT | R35: EY | S35: Manager | T35: 01/1998 | U35: 01/1999 | AB35: Consulting & Advisory | AC35: 35488 | AD35: 35766 | AE35: Associate Consultant | AH35: FALSE | AI35: FALSE
B36: 237 | C36: Alessio Ficara | D36: Ficara | E36: Alessio | F36: Fortunato | G36: 45-50 | I36: alessioficara@gmail.com | K36: https://www.linkedin.com/in/alessiofortunatoficara/ | L36: La Maison | M36: Guide-conférencier | N36: C Level | O36: Milan | P36: IT | Q36: Other / Unclassified | R36: Jobseeker | S36: Language Teacher | T36: 01/2018 | U36: Present | V36: Milan | Y36: IT | AB36: Technology & Software | AC36: 35831 | AD36: 37298 | AE36: Treasurer | AH36: TRUE | AI36: FALSE
A37: 127 | B37: 348 | C37: Alessio Loreti | D37: Loreti | E37: Alessio | G37: 45-50 | K37: https://www.linkedin.com/in/alessio-loreti/ | L37: Freelance Self-Employed | M37: Executive Director | O37: Marseille | P37: FR | Q37: Education & Research | R37: Queen Mary University of London | S37: Managing Director | T37: 09/2004 | U37: 03/2005 | V37: London | Y37: GB | AB37: Education & Research | AC37: 35831 | AD37: 36121 | AE37: Associate Consultant | AH37: FALSE | AI37: FALSE
A38: 91 | B38: 124 | C38: Alex Cecchini | D38: Cecchini | E38: Alex | G38: 50-55 | I38: alex.cecchini@me.com | K38: https://www.linkedin.com/ilex-cecchini-579278/ | L38: Bank J. Safra Sarasin Ltd | M38: Member Board Of Directors | N38: C Level | O38: Lugano | P38: IE | Q38: Financial Services | R38: LGT Private Banking | S38: Member of Boad of Directors | T38: 06/2019 | U38: 01/2022 | V38: Lugano | Y38: CH | AB38: Financial Services | AC38: 34236 | AD38: 34347 | AE38: Associate Consultant | AH38: FALSE | AI38: FALSE
A39: 141 | B39: 223 | C39: Alex Fattorini | D39: Fattorini | E39: Alex | G39: 45-50 | K39: https://www.linkedin.com/ilex-fattorini-263999/ | L39: Mcarthurglen Group | M39: Head of Strategy & Operations | N39: C Level | Q39: Consumer & Retail | R39: Primonial REIM Italy | S39: Consultant - Digital | T39: 09/2022 | V39: Milan | Y39: IT | AB39: Consulting & Advisory | AC39: 36280 | AD39: 36584 | AE39: Associate Consultant | AH39: FALSE | AI39: FALSE
B40: 606 | C40: Alice Zarantonello | D40: Zarantonello | E40: Alice | G40: 25-30 | I40: alicezarantonello@outlook.com | K40: https://www.linkedin.com/in/alice-zarantonello000/ | L40: HIOP | M40: President | N40: Middle Level | O40: Milan | P40: IT | Q40: Technology & Software | R40: McKinsey & Company | S40: Administrative Consultant | T40: 01/2022 | U40: 01/2024 | V40: Milan | Y40: IT | AB40: Technology & Software | AC40: 43255 | AD40: 43774 | AE40: Associate Consultant | AH40: FALSE | AI40: FALSE
...

Sheet People to contact
B2: Contact | C2: Surname | D2: Name | E2: LinkedIn | F2: Proj | G2: JEME4U | H2: Contacted | I2: Positive Answer | J2: Negative Answer | K2: Notes
B3: Maria | C3: Nichil | D3: =_xlfn.XLOOKUP('People to contact'!C3,#REF!,#REF!) -> #REF! | E3: https://www.linkedin.com/in/matteo-nichil-6b9189b/ | F3: x | H3: x
B4: Maria | C4: Almiento | D4: =_xlfn.XLOOKUP('People to contact'!C4,#REF!,#REF!) -> #REF! | E4: https://www.linkedin.com/in/giancarlo-almiento-951831/ | G4: x | H4: x
B5: Gio | C5: Benintende | D5: =_xlfn.XLOOKUP('People to contact'!C5,#REF!,#REF!) -> #REF! | E5: https://www.linkedin.com/in/francesco-benintende-4721a3 | G5: x | H5: x
C6: Brentel | D6: =_xlfn.XLOOKUP('People to contact'!C6,#REF!,#REF!) -> #REF! | E6: https://www.linkedin.com/in/stefano-brentel-4ba6a2 | G6: x | K6: do after Bain event
B7: Maria | C7: Cherubini | D7: =_xlfn.XLOOKUP('People to contact'!C7,#REF!,#REF!) -> #REF! | E7: https://www.linkedin.com/in/gianandrea-cherubini-82a431 | F7: x | G7: x | H7: x
B8: Gio | C8: Grabstein | D8: =_xlfn.XLOOKUP('People to contact'!C8,#REF!,#REF!) -> #REF! | E8: https://www.linkedin.com/in/simon-grabstein-a8425b/ | F8: x | H8: x
B9: Maria | C9: Lazzari | D9: =_xlfn.XLOOKUP('People to contact'!C9,#REF!,#REF!) -> #REF! | E9: https://www.linkedin.com/in/andrea-lazzari-94158519/ | F9: x | H9: x
B10: Maria | C10: Matuozzo | D10: =_xlfn.XLOOKUP('People to contact'!C10,#REF!,#REF!) -> #REF! | E10: https://www.linkedin.com/ilberto-matuozzo-2a54a8 | F10: x | H10: x
B11: Maria | C11: Pierantozzi | D11: =_xlfn.XLOOKUP('People to contact'!C11,#REF!,#REF!) -> #REF! | E11: https://www.linkedin.com/in/david-pierantozzi-0a44a5b/ | F11: x | H11: x
B12: Maria | C12: Alloisio | D12: =_xlfn.XLOOKUP('People to contact'!C12,#REF!,#REF!) -> #REF! | E12: https://www.linkedin.com/ilessandro-alloisio-9a13a/ | F12: x | H12: x
B13: Maria | C13: Benedetti del Rio | D13: =_xlfn.XLOOKUP('People to contact'!C13,#REF!,#REF!) -> #REF! | E13: https://www.linkedin.com/in/roberta-benedetti-del-rio-7a957b14/ | F13: x | H13: x
B14: Gio | C14: Benini | D14: =_xlfn.XLOOKUP('People to contact'!C14,#REF!,#REF!) -> #REF! | E14: https://www.linkedin.com/in/stefano-benini/ | F14: x | H14: x
B15: Maria | C15: Biancolin | D15: =_xlfn.XLOOKUP('People to contact'!C15,#REF!,#REF!) -> #REF! | E15: https://www.linkedin.com/in/michele-biancolin-863161/ | G15: x | H15: x
B16: Maria | C16: Bressan | D16: =_xlfn.XLOOKUP('People to contact'!C16,#REF!,#REF!) -> #REF! | E16: https://www.linkedin.com/ilessio-bressan-8b26b/ | F16: x | H16: x
B17: Maria | C17: Casati | D17: =_xlfn.XLOOKUP('People to contact'!C17,#REF!,#REF!) -> #REF! | E17: https://www.linkedin.com/in/stefano-casati-524b421/ | F17: x | H17: x
B18: Maria | C18: Cionini Visani | D18: =_xlfn.XLOOKUP('People to contact'!C18,#REF!,#REF!) -> #REF! | E18: https://www.linkedin.com/in/camilla-cionini-visani-581aa3/ | F18: x | H18: x
B19: Maria | C19: Conzi | D19: =_xlfn.XLOOKUP('People to contact'!C19,#REF!,#REF!) -> #REF! | E19: https://www.linkedin.com/in/giovanna-conzi-39a657/ | F19: x | H19: x
B20: Maria | C20: Del Grande | D20: =_xlfn.XLOOKUP('People to contact'!C20,#REF!,#REF!) -> #REF! | E20: https://www.linkedin.com/in/giacomodelgrande | F20: x | H20: x
B21: Gio | C21: Esentato | D21: =_xlfn.XLOOKUP('People to contact'!C21,#REF!,#REF!) -> #REF! | E21: https://www.linkedin.com/in/maurizio-g-esentato-922528a/ | F21: x | H21: x
C22: Fabbrini | D22: =_xlfn.XLOOKUP('People to contact'!C22,#REF!,#REF!) -> #REF! | E22: https://www.linkedin.com/in/francescofabbrini | G22: x | H22: x
C23: Fedel | D23: =_xlfn.XLOOKUP('People to contact'!C23,#REF!,#REF!) -> #REF! | E23: https://www.linkedin.com/in/fabiofedel/ | G23: x | H23: x
B24: Gio | C24: Fenaroli | D24: =_xlfn.XLOOKUP('People to contact'!C24,#REF!,#REF!) -> #REF! | E24: https://www.linkedin.com/in/fenarolimatteo | F24: x | H24: x
B25: Luca | C25: Ferrario | D25: =_xlfn.XLOOKUP('People to contact'!C25,#REF!,#REF!) -> #REF! | E25: https://www.linkedin.com/in/michele-ferrario-a464211/ | F25: x
B26: Maria | C26: Franchetti | D26: =_xlfn.XLOOKUP('People to contact'!C26,#REF!,#REF!) -> #REF! | E26: =_xlfn.XLOOKUP('People to contact'!C26,#REF!,#REF!) -> #REF! | F26: x | H26: x
C27: Galeandro | D27: =_xlfn.XLOOKUP('People to contact'!C27,#REF!,#REF!) -> #REF! | E27: =_xlfn.XLOOKUP('People to contact'!C27,#REF!,#REF!) -> #REF! | G27: x | H27: x
C28: Gardella | D28: =_xlfn.XLOOKUP('People to contact'!C28,#REF!,#REF!) -> #REF! | E28: =_xlfn.XLOOKUP('People to contact'!C28,#REF!,#REF!) -> #REF! | H28: x
B29: Gio | C29: Garosio | D29: =_xlfn.XLOOKUP('People to contact'!C29,#REF!,#REF!) -> #REF! | E29: =_xlfn.XLOOKUP('People to contact'!C29,#REF!,#REF!) -> #REF! | F29: x | H29: x
B30: Maria | C30: Giorgio | D30: =_xlfn.XLOOKUP('People to contact'!C30,#REF!,#REF!) -> #REF! | E30: =_xlfn.XLOOKUP('People to contact'!C30,#REF!,#REF!) -> #REF! | F30: x | H30: x
C31: Mariani | D31: =_xlfn.XLOOKUP('People to contact'!C31,#REF!,#REF!) -> #REF! | E31: =_xlfn.XLOOKUP('People to contact'!C31,#REF!,#REF!) -> #REF! | G31: x | H31: x
B32: Gio | C32: Mauri | D32: =_xlfn.XLOOKUP('People to contact'!C32,#REF!,#REF!) -> #REF! | E32: =_xlfn.XLOOKUP('People to contact'!C32,#REF!,#REF!) -> #REF! | F32: x | H32: x
B33: Gio | C33: Mento | D33: =_xlfn.XLOOKUP('People to contact'!C33,#REF!,#REF!) -> #REF! | E33: =_xlfn.XLOOKUP('People to contact'!C33,#REF!,#REF!) -> #REF! | F33: x | H33: x
B34: Gio | C34: Miglioranzi | D34: =_xlfn.XLOOKUP('People to contact'!C34,#REF!,#REF!) -> #REF! | E34: =_xlfn.XLOOKUP('People to contact'!C34,#REF!,#REF!) -> #REF! | F34: x | H34: x
C35: Moncalvo | D35: =_xlfn.XLOOKUP('People to contact'!C35,#REF!,#REF!) -> #REF! | E35: =_xlfn.XLOOKUP('People to contact'!C35,#REF!,#REF!) -> #REF! | F35: x | H35: x
B36: Maria | C36: Neytcheva | D36: =_xlfn.XLOOKUP('People to contact'!C36,#REF!,#REF!) -> #REF! | E36: =_xlfn.XLOOKUP('People to contact'!C36,#REF!,#REF!) -> #REF! | F36: x | H36: x | K36: To text in Bulgarian
B37: Gio | C37: Nuebling | D37: =_xlfn.XLOOKUP('People to contact'!C37,#REF!,#REF!) -> #REF! | E37: =_xlfn.XLOOKUP('People to contact'!C37,#REF!,#REF!) -> #REF! | F37: x | H37: x
B38: Gio | C38: Palacino | D38: =_xlfn.XLOOKUP('People to contact'!C38,#REF!,#REF!) -> #REF! | E38: =_xlfn.XLOOKUP('People to contact'!C38,#REF!,#REF!) -> #REF! | F38: x | H38: x
B39: Gio | C39: Podestà | D39: =_xlfn.XLOOKUP('People to contact'!C39,#REF!,#REF!) -> #REF! | E39: =_xlfn.XLOOKUP('People to contact'!C39,#REF!,#REF!) -> #REF! | F39: x | H39: x
B40: Gio | C40: Puddu | D40: =_xlfn.XLOOKUP('People to contact'!C40,#REF!,#REF!) -> #REF! | E40: =_xlfn.XLOOKUP('People to contact'!C40,#REF!,#REF!) -> #REF! | F40: x | H40: x
B41: Gio | C41: Puglisi | D41: =_xlfn.XLOOKUP('People to contact'!C41,#REF!,#REF!) -> #REF! | E41: =_xlfn.XLOOKUP('People to contact'!C41,#REF!,#REF!) -> #REF! | F41: x | H41: x
...

Sheet TMP
A1: Full Name | B1: First Name | C1: Middle Name(s) | D1: Second Name(s) | E1: E-mail Address | F1: E-mail Address #2 | G1: Mobile Phone #1 | H1: Mobile Phone #2 | I1: LinkedIn | J1: Firm #1 | K1: Role #1 | L1: Starting Month #1 | M1: Ending Month #1 | N1: Location #1 | O1: Industry #1 | P1: Firm #2 | Q1: Role #2 | R1: Starting Month #2 | S1: Ending Month #2 | T1: Location #2 | U1: Industry #2 | V1: JEME - Starting Period | W1: JEME - Ending Period | X1: JEME - Role #1 | Y1: JEME - Role #2 | Z1: JEME - Role #3
A2: Agnieszka Kania | B2: Agnieszka | D2: Kania | E2: lesniewska.agnieszka@gmail.com | I2: https://www.linkedin.com/agnieszkadariakania/ | J2: GSK | K2: Service Desk Manager | L2: 39722 | M2: 40148 | N2: Milan, Italy | O2: Pharmaceutical | P2: dotOne | Q2: Business Analyst | R2: 40911 | S2: 41279 | U2: Technology | X2: Associate Consultant
A3: Alberto Accogli | B3: Alberto | D3: Accogli | E3: alberto.accogli@gmail.com | G3: +39 328 628229 | I3: https://www.linkedin.com/alberto-accogli/ | J3: Amazon | K3: MBA Summer Intern | L3: 38626 | M3: 40513 | N3: Milan, Italy | O3: Retail | P3: Leoni Corporate Advisors | Q3: Junior Manager | R3: 40913 | S3: 43470 | U3: Consulting | V3: 38732 | W3: 39447 | X3: Secretary General
A4: Alberto Antoniolli | B4: Alberto | D4: Antoniolli | E4: alberto.antoniolli@gmail.com | G4: +39 342 6423569 | I4: https://www.linkedin.com/albertoantoniolli/ | J4: Lazard | K4: M&A Analyst | L4: 43497 | M4: 44896 | N4: Milan, Italy | O4: Advisory | P4: Italmobiliare SPA | Q4: Intern Financial Analyst | R4: 44202 | S4: 43474 | T4: Milan, Italy | U4: Investments | V4: 43626 | W4: 44743 | X4: Treasurer
A5: Alberto Cattaruzza | B5: Alberto | D5: Cattaruzza | E5: cattaruzza98@gmail.com | I5: https://www.linkedin.com/alberto-cattaruzza-84a1a196/ | J5: Bank of America | K5: Investment Banking Analyst | L5: 43891 | M5: 44470 | N5: Milan, Italy | O5: Investment Banking | P5: Italian Angels for Growth | R5: 43472 | S5: 43472 | T5: Milan, Italy | U5: Investments | X5: Associate Consultant
A6: Alberto Franco | B6: Alberto | D6: Franco | E6: alberto.franco@cbalex.com | G6: +39 348 862155 | I6: https://www.linkedin.com/albertofrancoit | J6: CBA Studio Legale e Tributario | N6: Milan, Italy | O6: Legal | P6: Università degli Studi di Torino | Q6: Professore a contratto | R6: 42005 | T6: Turin | U6: Education | X6: Associate Consultant
A7: Alberto Holler | B7: Alberto | D7: Holler | E7: alberto.holler@gmail.com | G7: +39 345 7151799 | I7: https://www.linkedin.com/alberto-holler-72a95199/ | J7: Generali | K7: M&A Analyst | L7: 43831 | M7: 44593 | N7: Milan, Italy | O7: Banking | P7: Deloitte | Q7: Summer Intern | R7: 44202 | S7: 44205 | T7: Milan, Italy | U7: Consulting | V7: 43843 | W7: 44627 | X7: Secretary General | Y7: Head of Internal Audit | Z7: Project Manager
A8: Alberto Matuozzo | B8: Alberto | D8: Matuozzo | E8: alberto_matuozzo@yahoo.co.uk | G8: +44 7919447118 | I8: https://www.linkedin.com/alberto-matuozzo-2a54a8 | J8: Farema Capital | K8: Partner | L8: 33970 | M8: 36160 | N8: London, United Kingdom | O8: Investment Banking | P8: Merian Capital LLP | Q8: Partner | R8: 44927 | S8: 40909 | U8: Investments | V8: 35104 | W8: 35766 | X8: Associate Consultant
A9: Alberto Vedovi | B9: Alberto | D9: Vedovi | E9: vedovia@gmail.com | I9: https://www.linkedin.com/alberto-vedovi-48832772 | J9: NS PARTNERS | L9: 42095 | M9: 43009 | N9: Luxemburg | O9: Private Equity | P9: Deloitte | Q9: Consultant | R9: 43472 | S9: 44570 | T9: Luxemburg | U9: Consulting | V9: 42159 | W9: 43059 | X9: Vice President | Y9: Tresaurer
A10: Aldo Pozzoli | B10: Aldo | D10: Pozzoli | E10: aldopozzoli@hotmail.com | I10: https://www.linkedin.com/aldopozzoli/ | J10: Accenture | K10: Principal Director | L10: 38353 | M10: 38353 | N10: Milan, Italy | O10: Consulting | P10: Comune di Milano | Q10: Consultant | R10: 44930 | S10: 40547 | T10: Milan, Italy | U10: Public Policy | V10: 36871 | W10: 37649 | X10: Associate Consultant
A11: Alessandra Arrigoni | B11: Alessandra | D11: Arrigoni | E11: alessandraarrigoni@hotmail.com | I11: https://www.linkedin.com/alessandra-arrigoni-8aa45b7/ | J11: NielsenIQ | K11: Client Business Partner | N11: London, United Kingdom | O11: Technology | P11: Nielsen | Q11: Consultant | R11: 44929 | S11: 42009 | T11: London, United Kingdom | U11: Technology | V11: 37642 | W11: 38007 | X11: Associate Consultant
A12: Alessandra Galli | B12: Alessandra | D12: Galli | E12: ale.galli76@gmail.com | G12: +39 347 73663 | V12: 35831 | W12: 35990 | X12: Associate Consultant
A13: Alessandra Mangeri | B13: Alessandra | D13: Mangeri | E13: ale.mangeri@virgilio.it | I13: https://www.linkedin.com/alessandra-mangeri-656893b/ | J13: AMG | K13: Tax Advisor | L13: 34335 | M13: 34335 | O13: Accounting | P13: Tribunale di Brescia | Q13: Advisor | R13: 40544 | T13: Brescia | U13: Advisory | V13: 33865 | W13: 37315 | X13: Associate Consultant
A14: Alessandra Peres | B14: Alessandra | D14: Peres | G14: +39 349 7865587 | I14: https://www.linkedin.com/alessandra-peres-21b2a2b/ | J14: Swiss Re Corporate Solutions | K14: Distribution Manager | L14: 39142 | M14: 40513 | N14: Milan, Italy | P14: FC Rimaco | Q14: Area Manager | R14: 44562 | S14: 44927 | T14: Lugano | U14: Insurance | V14: 39329 | W14: 40513 | X14: Associate Consultant
A15: Alessandra Vultaggio | B15: Alessandra | D15: Vultaggio | E15: alexvulty@gmail.com | G15: +39 349 4753351 | I15: https://www.linkedin.com/alessandravultaggio/ | J15: Global Blue | K15: Customer Value Creation Manager | L15: 35065 | M15: 37256 | N15: Milan, Italy | O15: Investments | P15: Edenred Italia | Q15: Director | R15: 40548 | S15: 43476 | T15: Milan, Italy | U15: Financial Services | V15: 35831 | W15: 37298 | X15: Associate Consultant
A16: Alessandro Alloisio | B16: Alessandro | D16: Alloisio | G16: +39 335 6843375 | I16: https://www.linkedin.com/alessandro-alloisio-9a13a/ | J16: Sanlorenzo Yacht | K16: Chief Information Officer | L16: 32874 | M16: 35064 | N16: Ameglia | O16: Construction | Q16: Freelancer | R16: 44564 | S16: 44197 | T16: Como | V16: 32464 | W16: 34233 | X16: Associate Consultant
A17: Alessandro Bellotti | B17: Alessandro | D17: Bellotti | V17: 32464 | W17: 33238 | X17: Associate Consultant
A18: Alessandro Brambilla | B18: Alessandro | D18: Brambilla | V18: 33419 | W18: 34466 | X18: Associate Consultant
A19: Alessandro Brutto | B19: Alessandro | D19: Brutto | E19: bruttoalessandro@gmail.com | G19: +39 338 7388 | I19: https://www.linkedin.com/alessandro-brutto-bb15117 | J19: Goldman Sachs | K19: Associate | L19: 42430 | M19: 42795 | N19: London, United Kingdom | O19: Investment Banking | P19: JP Morgan | Q19: Analyst | R19: 43471 | S19: 44197 | T19: London, United Kingdom | U19: Investment Banking | V19: 42513 | W19: 42790 | X19: Associate Consultant
A20: Alessandro Dadone | B20: Alessandro | D20: Dadone | E20: ale.dadone@gmail.com | I20: https://www.linkedin.com/alessandro-dadone-23196318 | J20: Casavo | K20: Head of Product | L20: 42614 | M20: 43466 | N20: Milan, Italy | O20: Investments | P20: Coca-Cola | Q20: Customer Marketing Intern | R20: 43106 | S20: 43109 | T20: Athens | U20: Food & Beverage | V20: 42751 | W20: 43472 | X20: Vice President
A21: Alessandro Filoramo | B21: Alessandro | D21: Filoramo | E21: alessandro.filoram@gmail.com | I21: https://www.linkedin.com/alessandrofiloramo | J21: Arthur D. Little | K21: Consultant | L21: 42614 | M21: 43497 | N21: Dubai | O21: Consulting | P21: IQVIA | Q21: Analyst | R21: 44570 | S21: 44203 | T21: Milan, Italy | X21: President
A22: Alessandro Gagliardi | B22: Alessandro | D22: Gagliardi | I22: https://www.linkedin.com/alessandro-gagliardi/ | J22: GE Capital | K22: Vice-President | L22: 44932 | M22: 42376 | N22: London, United Kingdom | O22: Banking | V22: 37013 | W22: 37298 | X22: Associate Consultant
A23: Alessandro Medico | B23: Alessandro | D23: Medico | E23: alemedi@icloud.com | I23: https://www.linkedin.com/alessandro-medico/ | J23: Amazon | K23: Intern | L23: 43709 | M23: 44573 | N23: Luxemburg | O23: Retail | P23: Bending Spoons | Q23: M&A Intern | R23: 44197 | S23: 44565 | T23: Milan, Italy | U23: Technology | V23: 43843 | X23: Associate Consultant
A24: Alessandro Radici | B24: Alessandro | D24: Radici | E24: alessandro.radici@seragro.com.ar | G24: 973 6522374 | H24: 9 2664 957555 | I24: https://www.linkedin.com/alessandro-radici-9988317/ | J24: SER BEEF | K24: President | L24: 38718 | M24: 39082 | N24: San Luis | O24: Consulting | P24: McKinsey & Company | R24: 40916 | S24: 42011 | T24: New Jersey | U24: Consulting | V24: 38356 | W24: 39083 | X24: Associate Consultant
A25: Alessandro Trisciuoglio | B25: Alessandro | D25: Trisciuoglio | E25: aletrisc@gmail.com | I25: https://www.linkedin.com/alessandro-trisciuoglio/ | J25: Booking.com | K25: Self Employed | L25: 44197 | M25: 44805 | N25: Diano Marina | P25: Beko | Q25: Intern | R25: 44563 | S25: 44928 | T25: Milan, Italy | U25: Consumer Goods | X25: Associate Consultant
A26: Alessia Acquistapace | B26: Alessia | D26: Acquistapace | I26: https://www.linkedin.com/alessia-acquistapace-22972165/ | J26: Amazon | K26: Financial Analyst | L26: 42979 | M26: 44835 | N26: Luxemburg | O26: Retail | P26: Rothshild & Co. | Q26: Intern | R26: 44202 | S26: 44197 | T26: Milan, Italy | U26: Investment Banking | V26: 43255 | X26: Associate Consultant
A27: Alessia Alberti | B27: Alessia | D27: Alberti | E27: alessia.alberti96@gmail.com | I27: https://www.linkedin.com/alessia-alberti-b75a612b/ | J27: Roveda Laurini Clerici D’Amore Notai | K27: Praticante Notaio | L27: 43252 | M27: 43862 | N27: Milan, Italy | O27: Legal | P27: Bonelli Erede | Q27: Praticante Avvocato | R27: 44563 | S27: 44568 | T27: Milan, Italy | U27: Legal | V27: 43255 | W27: 43871 | X27: Associate Consultant
A28: Alessia Della Vedova | B28: Alessia | D28: Della Vedova | G28: +39 338 272557 | I28: https://www.linkedin.com/alessia-dellavedova/ | J28: Russo De Rosa Associati | K28: Dottore Commercialista - Revisore Legale | L28: 33970 | M28: 36160 | O28: Legal | P28: Fieldfisher - Studio Associato Servizi Professionali Integrati | Q28: Dottore Commercialista - Revisore Legale | R28: 43102 | S28: 43473 | T28: Milan, Italy | U28: Legal | V28: 35831 | W28: 36121 | X28: Associate Consultant
A29: Alessia Fontanari | B29: Alessia | D29: Fontanari | E29: alessia.fon@gmail.com | I29: https://www.linkedin.com/alessiafontanari | J29: Doctolib | K29: Strategy Manager | L29: 41275 | M29: 42401 | N29: Milan, Italy | O29: Medical/Healthcare | P29: McKinsey & Company | Q29: Associate | R29: 44197 | S29: 44208 | T29: Milan, Italy | U29: Consulting | V29: 41310 | W29: 42499 | X29: Head of Sales
A30: Alessio Bressan | B30: Alessio | D30: Bressan | E30: alessio.bressan@igbressan.it | I30: https://www.linkedin.com/alessio-bressan-8b26b/ | J30: IGB - Industrie Grafiche Bressan | K30: CEO | L30: 33604 | M30: 36160 | N30: Milan, Italy | O30: Retail | P30: EY | Q30: Consultant | S30: 1/1/1099 | U30: Consulting | V30: 35488 | W30: 35766 | X30: Associate Consultant
A31: Alessio Fortunato Ficara | B31: Alessio | C31: Fortunato | D31: Ficara | E31: alessioficara@gmail.com | I31: https://www.linkedin.com/alessiofortunatoficara/ | J31: La Maison - la tua casa su misura | K31: Titolare | L31: 34700 | M31: 36891 | N31: Milan, Italy | O31: Retail | P31: Jobseeker | Q31: Manager | R31: 43101 | U31: Technology | V31: 35831 | W31: 37298 | X31: Associate Consultant
A32: Alessio Loreti | B32: Alessio | D32: Loreti | G32: +39 347 351471 | V32: 35831 | W32: 36121 | X32: Associate Consultant
A33: Alex Cecchini | B33: Alex | D33: Cecchini | E33: alex.cecchini@me.com | I33: https://www.linkedin.com/alex-cecchini-579278/ | J33: Bank J. Safra Sarasin Ltd | K33: Executive Director | L33: 32509 | M33: 34699 | N33: Lugano | O33: Banking | P33: LGT – Private Banking und Asset Management | Q33: Managing Director | R33: 43471 | S33: 44562 | T33: Lugano | U33: Banking | V33: 34236 | W33: 34347 | X33: Associate Consultant
A34: Alex Fattorini | B34: Alex | D34: Fattorini | G34: +39 338 7775421 | I34: https://www.linkedin.com/alex-fattorini-263999/ | J34: Primonial Reim Italy | K34: Member of Boad of Directors | L34: 36161 | M34: 36526 | N34: Milan, Italy | P34: DGPA & Co. | Q34: Partner | R34: 42744 | T34: Milan, Italy | U34: Consulting | V34: 36280 | W34: 36584 | X34: Associate Consultant
A35: Alice Zarantonello | B35: Alice | D35: Zarantonello | E35: alicezarantonello@outlook.com | I35: https://www.linkedin.com/alice-zarantonello/ | J35: McKinsey & Company | K35: Junior Associate | L35: 43221 | M35: 43739 | N35: Milan, Italy | O35: Consulting | P35: Microsoft | Q35: Product Marketing Manager | R35: 44198 | S35: 44570 | T35: Milan, Italy | U35: Technology | V35: 43255 | W35: 43774 | X35: Associate Consultant
A36: Alvise Biffi | B36: Alvise | D36: Biffi | E36: a.biffi@securenetwork.it | G36: +39 338 9925329 | I36: https://www.linkedin.com/alvise-biffi-115aa5/ | J36: Secure Network Srl | K36: CEO | L36: 36161 | M36: 36861 | N36: Milan, Italy | O36: Technology | P36: Assolombarda | Q36: Vicepresidente | R36: 44930 | T36: Milan, Italy | U36: Public Policy | V36: 36280 | W36: 37649 | X36: President
A37: Amin Harbi | B37: Amin | D37: Harbi | E37: aharbi13@gmail.com | I37: https://www.linkedin.com/amin-harbi/ | J37: Boston Consulting Group | K37: Intern | L37: 43374 | M37: 44713 | N37: Milan, Italy | O37: Consulting | P37: HSBC | Q37: Intern | R37: 44566 | S37: 44562 | T37: Milan, Italy | U37: Banking | V37: 43480 | X37: Associate Consultant
A38: André Gardella | B38: André | D38: Gardella | E38: agardelik@gmail.com | I38: https://www.linkedin.com/andre-gardella-67734/ | J38: Treezor | K38: CEO | L38: 33970 | M38: 35064 | N38: Paris | P38: Société Générale | Q38: Head of Operations and Transformation | R38: 43472 | S38: 44927 | T38: Paris | U38: Banking | V38: 34236 | W38: 34824 | X38: International Manager
A39: Andrea Augusto Baroni | B39: Andrea | C39: Augusto | D39: Baroni | E39: andrea.augusto.baroni@gmail.com | I39: https://www.linkedin.com/aabaroni/ | J39: Barclays | K39: VP Data Science | L39: 41548 | M39: 42278 | N39: London, United Kingdom | O39: Banking | P39: Travelport | Q39: Lead Data Scientist | R39: 42741 | S39: 43105 | T39: London, United Kingdom | U39: Technology | V39: 41666 | W39: 42268 | X39: Treasurer
A40: Andrea Bergamini | B40: Andrea | D40: Bergamini | E40: anbergamini@gmail.com | G40: +39 338 5455938 | I40: https://www.linkedin.com/andrea-bergamini-4695b6/ | J40: Electrolux | K40: European Category Director | L40: 38838 | M40: 39722 | N40: Stockholm | O40: Technology | P40: Whirpool | Q40: Strategic Planner Manager | R40: 42008 | S40: 42016 | T40: Comerio | U40: Technology | V40: 38860 | W40: 39882 | X40: Vice President
...

Sheet Mesi
B2: gen | C2: 1
B3: feb | C3: 2
B4: mar | C4: 3
B5: apr | C5: 4
B6: mag | C6: 5
B7: giu | C7: 6
B8: lug | C8: 7
B9: ago | C9: 8
B10: set | C10: 9
B11: ott | C11: 10
B12: nov | C12: 11
B13: dic | C13: 12
... B26: Dec | C26: 12

Sheet Industries
A1: Agriculture | B1: =SUM(COUNTIF(#REF!,A1),COUNTIF(#REF!,A1)) -> #REF! | D1: Accounting | E1: 6 | G1: =IF(O2=OR("AI","Business Intelligence", "Computer Software", "Cyber Security", "Information", "Internet", "IT", "IT & Communication", "Tech", "TLC"), "Technology", IF(O2=OR("Construction","Shipbuilding","Maritime"), "Construction", IF(O2 = OR("Public Administration", "Institution", "Public Policy"), "Public Policy", IF( O2 = OR("Management", "Consulting Advisory", "Management Consulting"), "Consulting", IF( O2 = OR("Publishing", "Marketing & Advertising", "Media"), "Media & Marketing", IF( O2 = OR("Electrical/Electronic Manufacturing", "Oil & Energy"), "Energy", IF( O2 = OR("Real Estate", "Fondo (inclusi PE)"), "Investments", IF( O2 = OR("Research", "University"), "Education", O2)))))))) -> #VALUE!
A2: AI | B2: =SUM(COUNTIF(#REF!,A2),COUNTIF(#REF!,A2)) -> #REF! | C2: 1 | D2: Advisory | E2: 6
A3: Business Intelligence | B3: =SUM(COUNTIF(#REF!,A3),COUNTIF(#REF!,A3)) -> #REF! | C3: 1
A4: Construction | B4: =SUM(COUNTIF(#REF!,A4),COUNTIF(#REF!,A4)) -> #REF! | C4: 1 | D4: Automotive | E4: 9
A5: Cyber Security | B5: =SUM(COUNTIF(#REF!,A5),COUNTIF(#REF!,A5)) -> #REF! | C5: 1 | D5: Banking | E5: 87
A6: IT | B6: =SUM(COUNTIF(#REF!,A6),COUNTIF(#REF!,A6)) -> #REF! | C6: 1
A7: Management | B7: =SUM(COUNTIF(#REF!,A7),COUNTIF(#REF!,A7)) -> #REF! | C7: 1 | D7: Consumer goods | E7: 14
A8: Public Administration | B8: =SUM(COUNTIF(#REF!,A8),COUNTIF(#REF!,A8)) -> #REF! | C8: 1 | D8: Corporate Finance | E8: 38
A9: Publishing | B9: =SUM(COUNTIF(#REF!,A9),COUNTIF(#REF!,A9)) -> #REF! | C9: 1
A10: Shipbuilding | B10: =SUM(COUNTIF(#REF!,A10),COUNTIF(#REF!,A10)) -> #REF! | C10: 1 | D10: Defense | E10: 2
A11: Consulting Advisory | B11: =SUM(COUNTIF(#REF!,A11),COUNTIF(#REF!,A11)) -> #REF! | C11: 1 | D11: Education | E11: 35
A12: Energy | B12: =SUM(COUNTIF(#REF!,A12),COUNTIF(#REF!,A12)) -> #REF! | C12: 1 | D12: Engineering | E12: 1
A13: Information | B13: =SUM(COUNTIF(#REF!,A13),COUNTIF(#REF!,A13)) -> #REF! | C13: 1 | D13: Entertainment | E13: 8
A14: Marketing & Advertising | B14: =SUM(COUNTIF(#REF!,A14),COUNTIF(#REF!,A14)) -> #REF! | C14: 1 | D14: Fashion | E14: 4
A15: University | B15: =SUM(COUNTIF(#REF!,A15),COUNTIF(#REF!,A15)) -> #REF! | C15: 1 | D15: Food & Beverage | E15: 15
A16: Maritime | B16: =SUM(COUNTIF(#REF!,A16),COUNTIF(#REF!,A16)) -> #REF! | C16: 1
A17: Electrical/Electronic Manufacturing | B17: =SUM(COUNTIF(#REF!,A17),COUNTIF(#REF!,A17)) -> #REF! | C17: 1
A18: Institution | B18: =SUM(COUNTIF(#REF!,A18),COUNTIF(#REF!,A18)) -> #REF! | C18: 1
A19: Real Estate | B19: =SUM(COUNTIF(#REF!,A19),COUNTIF(#REF!,A19)) -> #REF! | C19: 1
A20: Research | B20: =SUM(COUNTIF(#REF!,A20),COUNTIF(#REF!,A20)) -> #REF! | C20: 1
A21: Media | B21: =SUM(COUNTIF(#REF!,A21),COUNTIF(#REF!,A21)) -> #REF! | C21: 1 | D21: Logistics & Supply Chain | E21: 5
A22: Fondo (inclusi PE) | B22: =SUM(COUNTIF(#REF!,A22),COUNTIF(#REF!,A22)) -> #REF! | C22: 1
A23: TLC | B23: =SUM(COUNTIF(#REF!,A23),COUNTIF(#REF!,A23)) -> #REF! | C23: 1
A24: Computer Software | B24: =SUM(COUNTIF(#REF!,A24),COUNTIF(#REF!,A24)) -> #REF! | C24: 1
A25: Oil & Energy | B25: =SUM(COUNTIF(#REF!,A25),COUNTIF(#REF!,A25)) -> #REF! | C25: 1 | D25: Non profit | E25: 4
A26: Tech | B26: =SUM(COUNTIF(#REF!,A26),COUNTIF(#REF!,A26)) -> #REF! | C26: 1
A27: Technology | B27: =SUM(COUNTIF(#REF!,A27),COUNTIF(#REF!,A27)) -> #REF! | C27: 1 | D27: Private Equity | E27: 24
A28: Internet | B28: =SUM(COUNTIF(#REF!,A28),COUNTIF(#REF!,A28)) -> #REF! | C28: 1
A29: Public Policy | B29: =SUM(COUNTIF(#REF!,A29),COUNTIF(#REF!,A29)) -> #REF! | C29: 1 | D29: Public Policy | E29: 17
A30: IT & Communication | B30: =SUM(COUNTIF(#REF!,A30),COUNTIF(#REF!,A30)) -> #REF! | C30: 1
A31: Investments | B31: =SUM(COUNTIF(#REF!,A31),COUNTIF(#REF!,A31)) -> #REF! | C31: 1
A32: Management Consulting | B32: =SUM(COUNTIF(#REF!,A32),COUNTIF(#REF!,A32)) -> #REF! | C32: 1 | D32: Sustainabilty | E32: 2
A33: Education | B33: =SUM(COUNTIF(#REF!,A33),COUNTIF(#REF!,A33)) -> #REF! | C33: 1
A34: Consulting | B34: =SUM(COUNTIF(#REF!,A34),COUNTIF(#REF!,A34)) -> #REF! | C34: 1
A35: Altro | B35: =SUM(COUNTIF(#REF!,A35),COUNTIF(#REF!,A35)) -> #REF! | C35: 1 | D35: Agriculture | E35: 1
A36: Art | B36: =SUM(COUNTIF(#REF!,A36),COUNTIF(#REF!,A36)) -> #REF! | C36: 1
A37: Business Development | B37: =SUM(COUNTIF(#REF!,A37),COUNTIF(#REF!,A37)) -> #REF! | C37: 1
A38: E-commerce | B38: =SUM(COUNTIF(#REF!,A38),COUNTIF(#REF!,A38)) -> #REF! | C38: 1 | D38: Beauty & Cosmetics | E38: 4
A39: Engineering | B39: =SUM(COUNTIF(#REF!,A39),COUNTIF(#REF!,A39)) -> #REF!
A40: Event management | B40: =SUM(COUNTIF(#REF!,A40),COUNTIF(#REF!,A40)) -> #REF! | C40: 1
...
